Output from /home/x_zhzhu/RoboSaGA/robomimic/robomimic/scripts/eval_trained_agent.py with arguments --agent ../experiments/robosaga/lift_image/bc_rnn/overlay/20240524140242/models/model_epoch_160.pth --n_rollouts 50 --texture_category indoor --env_id indoor_env_1 --video_path ../experiments/robosaga/lift_image/bc_rnn/overlay/20240524140242/eval/videos/indoor_ckpt_model_epoch_160.mp4:

Output from /home/x_zhzhu/RoboSaGA/robomimic/robomimic/scripts/eval_trained_agent.py with arguments --agent ../experiments/robosaga/lift_image/bc_rnn/overlay/20240524140242/models/model_epoch_140.pth --n_rollouts 50 --texture_category indoor --env_id indoor_env_2 --video_path ../experiments/robosaga/lift_image/bc_rnn/overlay/20240524140242/eval/videos/indoor_ckpt_model_epoch_140.mp4:

Output from /home/x_zhzhu/RoboSaGA/robomimic/robomimic/scripts/eval_trained_agent.py with arguments --agent ../experiments/robosaga/lift_image/bc_rnn/overlay/20240524140242/models/model_epoch_180.pth --n_rollouts 50 --texture_category indoor --env_id indoor_env_0 --video_path ../experiments/robosaga/lift_image/bc_rnn/overlay/20240524140242/eval/videos/indoor_ckpt_model_epoch_180.mp4:

Errors: Traceback (most recent call last):
  File "/home/x_zhzhu/RoboSaGA/robomimic/robomimic/scripts/eval_trained_agent.py", line 474, in <module>
    run_trained_agent(args)
  File "/home/x_zhzhu/RoboSaGA/robomimic/robomimic/scripts/eval_trained_agent.py", line 247, in run_trained_agent
    policy, ckpt_dict = FileUtils.policy_from_checkpoint(
  File "/home/x_zhzhu/RoboSaGA/robomimic/robomimic/utils/file_utils.py", line 320, in policy_from_checkpoint
    ckpt_dict = maybe_dict_from_checkpoint(ckpt_path=ckpt_path, ckpt_dict=ckpt_dict)
  File "/home/x_zhzhu/RoboSaGA/robomimic/robomimic/utils/file_utils.py", line 236, in maybe_dict_from_checkpoint
    ckpt_dict = load_dict_from_checkpoint(ckpt_path)
  File "/home/x_zhzhu/RoboSaGA/robomimic/robomimic/utils/file_utils.py", line 216, in load_dict_from_checkpoint
    ckpt_dict = torch.load(ckpt_path)
  File "/home/x_zhzhu/.conda/envs/robosaga/lib/python3.8/site-packages/torch/serialization.py", line 712, in load
    return _load(opened_zipfile, map_location, pickle_module, **pickle_load_args)
  File "/home/x_zhzhu/.conda/envs/robosaga/lib/python3.8/site-packages/torch/serialization.py", line 1049, in _load
    result = unpickler.load()
  File "/home/x_zhzhu/.conda/envs/robosaga/lib/python3.8/site-packages/torch/serialization.py", line 1019, in persistent_load
    load_tensor(dtype, nbytes, key, _maybe_decode_ascii(location))
  File "/home/x_zhzhu/.conda/envs/robosaga/lib/python3.8/site-packages/torch/serialization.py", line 1001, in load_tensor
    wrap_storage=restore_location(storage, location),
  File "/home/x_zhzhu/.conda/envs/robosaga/lib/python3.8/site-packages/torch/serialization.py", line 175, in default_restore_location
    result = fn(storage, location)
  File "/home/x_zhzhu/.conda/envs/robosaga/lib/python3.8/site-packages/torch/serialization.py", line 157, in _cuda_deserialize
    return obj.cuda(device)
  File "/home/x_zhzhu/.conda/envs/robosaga/lib/python3.8/site-packages/torch/_utils.py", line 78, in _cuda
    return torch._UntypedStorage(self.size(), device=torch.device('cuda')).copy_(self, non_blocking)
RuntimeError: CUDA error: all CUDA-capable devices are busy or unavailable
CUDA kernel errors might be asynchronously reported at some other API call,so the stacktrace below might be incorrect.
For debugging consider passing CUDA_LAUNCH_BLOCKING=1.


===== Results for ../experiments/robosaga/lift_image/bc_rnn/overlay/20240524140242/ =====
Indomain: [1.0, 1.0, 1.0], 1.0 +/- 0.0
  data: [1.0, 1.0, 1.0]
Off-domain for indoor: nan +/- nan
   data: []
