Output from /home/zheyu/RoboSaGA/robomimic/robomimic/scripts/eval_trained_agent.py with arguments --agent ../experiments/robosaga/lift_image/bc/saga/20240531120025/models/model_epoch_100_Lift_success_1.0.pth --n_rollouts 50 --distractors --video_path ../experiments/robosaga/lift_image/bc/saga/20240531120025/eval/videos/distractors_ckpt_model_epoch_100_Lift_success_1.0.mp4:

Output from /home/zheyu/RoboSaGA/robomimic/robomimic/scripts/eval_trained_agent.py with arguments --agent ../experiments/robosaga/lift_image/bc/saga/20240531120025/models/model_epoch_200.pth --n_rollouts 50 --distractors --video_path ../experiments/robosaga/lift_image/bc/saga/20240531120025/eval/videos/distractors_ckpt_model_epoch_200.mp4:

Output from /home/zheyu/RoboSaGA/robomimic/robomimic/scripts/eval_trained_agent.py with arguments --agent ../experiments/robosaga/lift_image/bc/saga/20240531120025/models/model_epoch_50_Lift_success_0.95.pth --n_rollouts 50 --distractors --video_path ../experiments/robosaga/lift_image/bc/saga/20240531120025/eval/videos/distractors_ckpt_model_epoch_50_Lift_success_0.95.mp4:

Errors: Traceback (most recent call last):
  File "/home/zheyu/RoboSaGA/robomimic/robomimic/scripts/eval_trained_agent.py", line 497, in <module>
    run_trained_agent(args)
  File "/home/zheyu/RoboSaGA/robomimic/robomimic/scripts/eval_trained_agent.py", line 274, in run_trained_agent
    policy, ckpt_dict = FileUtils.policy_from_checkpoint(
  File "/home/zheyu/RoboSaGA/robomimic/robomimic/utils/file_utils.py", line 320, in policy_from_checkpoint
    ckpt_dict = maybe_dict_from_checkpoint(ckpt_path=ckpt_path, ckpt_dict=ckpt_dict)
  File "/home/zheyu/RoboSaGA/robomimic/robomimic/utils/file_utils.py", line 236, in maybe_dict_from_checkpoint
    ckpt_dict = load_dict_from_checkpoint(ckpt_path)
  File "/home/zheyu/RoboSaGA/robomimic/robomimic/utils/file_utils.py", line 216, in load_dict_from_checkpoint
    ckpt_dict = torch.load(ckpt_path)
  File "/home/zheyu/Anaconda/envs/robosaga/lib/python3.8/site-packages/torch/serialization.py", line 712, in load
    return _load(opened_zipfile, map_location, pickle_module, **pickle_load_args)
  File "/home/zheyu/Anaconda/envs/robosaga/lib/python3.8/site-packages/torch/serialization.py", line 1049, in _load
    result = unpickler.load()
  File "/home/zheyu/Anaconda/envs/robosaga/lib/python3.8/site-packages/torch/serialization.py", line 1019, in persistent_load
    load_tensor(dtype, nbytes, key, _maybe_decode_ascii(location))
  File "/home/zheyu/Anaconda/envs/robosaga/lib/python3.8/site-packages/torch/serialization.py", line 1001, in load_tensor
    wrap_storage=restore_location(storage, location),
  File "/home/zheyu/Anaconda/envs/robosaga/lib/python3.8/site-packages/torch/serialization.py", line 175, in default_restore_location
    result = fn(storage, location)
  File "/home/zheyu/Anaconda/envs/robosaga/lib/python3.8/site-packages/torch/serialization.py", line 157, in _cuda_deserialize
    return obj.cuda(device)
  File "/home/zheyu/Anaconda/envs/robosaga/lib/python3.8/site-packages/torch/_utils.py", line 78, in _cuda
    return torch._UntypedStorage(self.size(), device=torch.device('cuda')).copy_(self, non_blocking)
RuntimeError: CUDA error: out of memory
CUDA kernel errors might be asynchronously reported at some other API call,so the stacktrace below might be incorrect.
For debugging consider passing CUDA_LAUNCH_BLOCKING=1.


===== Results for ../experiments/robosaga/lift_image/bc/saga/20240531120025/ =====
Indomain: [1.0, 1.0, 0.95], 0.98 +/- 0.02
  data: [1.0, 1.0, 0.95]
Off-domain for distractors: nan +/- nan
   data: []
